<?xml version="1.0" encoding="utf-8"?>
<!-- This URDF was automatically created by SolidWorks to URDF Exporter! Originally created by Stephen Brawner (brawner@gmail.com) 
     Commit Version: 1.6.0-4-g7f85cfe  Build Version: 1.6.7995.38578
     For more information, please see http://wiki.ros.org/sw_urdf_exporter -->
<robot
  name="urdf_testingdoc">
  <link
    name="base_link">
    <inertial>
      <origin
        xyz="9.7454E-19 0 0.05"
        rpy="0 0 0" />
      <mass
        value="0.7854" />
      <inertia
        ixx="0.0011454"
        ixy="0"
        ixz="9.1794E-36"
        iyy="0.0011454"
        iyz="3.7944E-36"
        izz="0.00098175" />
    </inertial>
    <visual>
      <origin
        xyz="0 0 0"
        rpy="0 0 0" />
      <geometry>
        <mesh
          filename="package://urdf_testingdoc/meshes/base_link.STL" />
      </geometry>
      <material
        name="">
        <color
          rgba="0.79216 0.81961 0.93333 1" />
      </material>
    </visual>
    <collision>
      <origin
        xyz="0 0 0"
        rpy="0 0 0" />
      <geometry>
        <mesh
          filename="package://urdf_testingdoc/meshes/base_link.STL" />
      </geometry>
    </collision>
  </link>
  <link
    name="Link_1">
    <inertial>
      <origin
        xyz="-1.5371E-17 2.2386E-17 -0.0091527"
        rpy="0 0 0" />
      <mass
        value="0.53967" />
      <inertia
        ixx="0.0011605"
        ixy="1.199E-20"
        ixz="-9.7615E-20"
        iyy="0.00091418"
        iyz="7.9409E-20"
        izz="0.001119" />
    </inertial>
    <visual>
      <origin
        xyz="0 0 0"
        rpy="0 0 0" />
      <geometry>
        <mesh
          filename="package://urdf_testingdoc/meshes/Link_1.STL" />
      </geometry>
      <material
        name="">
        <color
          rgba="0.79216 0.81961 0.93333 1" />
      </material>
    </visual>
    <collision>
      <origin
        xyz="0 0 0"
        rpy="0 0 0" />
      <geometry>
        <mesh
          filename="package://urdf_testingdoc/meshes/Link_1.STL" />
      </geometry>
    </collision>
  </link>
  <joint
    name="Joint_1"
    type="continuous">
    <origin
      xyz="0 0 0.155"
      rpy="0 0 0" />
    <parent
      link="base_link" />
    <child
      link="Link_1" />
    <axis
      xyz="0 0 1" />
  </joint>
  <link
    name="Link_2">
    <inertial>
      <origin
        xyz="0.13864 2.0834E-17 0"
        rpy="0 0 0" />
      <mass
        value="0.74997" />
      <inertia
        ixx="0.00032961"
        ixy="-5.873E-20"
        ixz="3.0918E-20"
        iyy="0.0066953"
        iyz="2.7209E-21"
        izz="0.0065773" />
    </inertial>
    <visual>
      <origin
        xyz="0 0 0"
        rpy="0 0 0" />
      <geometry>
        <mesh
          filename="package://urdf_testingdoc/meshes/Link_2.STL" />
      </geometry>
      <material
        name="">
        <color
          rgba="0.79216 0.81961 0.93333 1" />
      </material>
    </visual>
    <collision>
      <origin
        xyz="0 0 0"
        rpy="0 0 0" />
      <geometry>
        <mesh
          filename="package://urdf_testingdoc/meshes/Link_2.STL" />
      </geometry>
    </collision>
  </link>
  <joint
    name="Joint_2"
    type="continuous">
    <origin
      xyz="0 0 0"
      rpy="0 0 0" />
    <parent
      link="Link_1" />
    <child
      link="Link_2" />
    <axis
      xyz="0 -1 0" />
  </joint>
  <link
    name="Link_3">
    <inertial>
      <origin
        xyz="0 1.667E-17 -0.03481"
        rpy="0 0 0" />
      <mass
        value="0.13785" />
      <inertia
        ixx="0.00016386"
        ixy="-1.2466E-20"
        ixz="4.1059E-20"
        iyy="0.00019813"
        iyz="-1.3191E-21"
        izz="4.3399E-05" />
    </inertial>
    <visual>
      <origin
        xyz="0 0 0"
        rpy="0 0 0" />
      <geometry>
        <mesh
          filename="package://urdf_testingdoc/meshes/Link_3.STL" />
      </geometry>
      <material
        name="">
        <color
          rgba="0.79216 0.81961 0.93333 1" />
      </material>
    </visual>
    <collision>
      <origin
        xyz="0 0 0"
        rpy="0 0 0" />
      <geometry>
        <mesh
          filename="package://urdf_testingdoc/meshes/Link_3.STL" />
      </geometry>
    </collision>
  </link>
  <joint
    name="Joint_3"
    type="continuous">
    <origin
      xyz="0.3 0 0"
      rpy="0 0 0" />
    <parent
      link="Link_2" />
    <child
      link="Link_3" />
    <axis
      xyz="0 -1 0" />
  </joint>
  <link
    name="Link_4">
    <inertial>
      <origin
        xyz="0 0.00097479 -0.1031"
        rpy="0 0 0" />
      <mass
        value="0.33463" />
      <inertia
        ixx="0.0011137"
        ixy="-6.1196E-21"
        ixz="-3.057E-19"
        iyy="0.0011883"
        iyz="3.0598E-05"
        izz="0.00012385" />
    </inertial>
    <visual>
      <origin
        xyz="0 0 0"
        rpy="0 0 0" />
      <geometry>
        <mesh
          filename="package://urdf_testingdoc/meshes/Link_4.STL" />
      </geometry>
      <material
        name="">
        <color
          rgba="0.79216 0.81961 0.93333 1" />
      </material>
    </visual>
    <collision>
      <origin
        xyz="0 0 0"
        rpy="0 0 0" />
      <geometry>
        <mesh
          filename="package://urdf_testingdoc/meshes/Link_4.STL" />
      </geometry>
    </collision>
  </link>
  <joint
    name="Joint_4"
    type="continuous">
    <origin
      xyz="0 0 -0.1"
      rpy="0 0 0" />
    <parent
      link="Link_3" />
    <child
      link="Link_4" />
    <axis
      xyz="0 0 -1" />
  </joint>
  <link
    name="Link_5">
    <inertial>
      <origin
        xyz="0 -0.0020572 -0.045954"
        rpy="0 0 0" />
      <mass
        value="0.15856" />
      <inertia
        ixx="0.00017405"
        ixy="-1.8717E-20"
        ixz="-6.649E-20"
        iyy="0.00020851"
        iyz="1.3978E-05"
        izz="5.664E-05" />
    </inertial>
    <visual>
      <origin
        xyz="0 0 0"
        rpy="0 0 0" />
      <geometry>
        <mesh
          filename="package://urdf_testingdoc/meshes/Link_5.STL" />
      </geometry>
      <material
        name="">
        <color
          rgba="0.79216 0.81961 0.93333 1" />
      </material>
    </visual>
    <collision>
      <origin
        xyz="0 0 0"
        rpy="0 0 0" />
      <geometry>
        <mesh
          filename="package://urdf_testingdoc/meshes/Link_5.STL" />
      </geometry>
    </collision>
  </link>
  <joint
    name="Joint_5"
    type="continuous">
    <origin
      xyz="0 0 -0.2"
      rpy="0 0 0" />
    <parent
      link="Link_4" />
    <child
      link="Link_5" />
    <axis
      xyz="0 1 0" />
  </joint>
  <link
    name="end_point">
    <inertial>
      <origin
        xyz="0.00025683 -0.00025684 -0.023934"
        rpy="0 0 0" />
      <mass
        value="0.06096" />
      <inertia
        ixx="1.3816E-05"
        ixy="-4.0305E-09"
        ixz="4.081E-07"
        iyy="2.44E-05"
        iyz="-4.0811E-07"
        izz="1.9457E-05" />
    </inertial>
    <visual>
      <origin
        xyz="0 0 0"
        rpy="0 0 0" />
      <geometry>
        <mesh
          filename="package://urdf_testingdoc/meshes/end_point.STL" />
      </geometry>
      <material
        name="">
        <color
          rgba="0.79216 0.81961 0.93333 1" />
      </material>
    </visual>
    <collision>
      <origin
        xyz="0 0 0"
        rpy="0 0 0" />
      <geometry>
        <mesh
          filename="package://urdf_testingdoc/meshes/end_point.STL" />
      </geometry>
    </collision>
  </link>
  <joint
    name="Joint_6"
    type="continuous">
    <origin
      xyz="0 0 -0.1"
      rpy="0 0 0" />
    <parent
      link="Link_5" />
    <child
      link="end_point" />
    <axis
      xyz="0 0 -1" />
  </joint>
</robot>