<?xml version="1.0" encoding="utf-8"?>
<!-- This URDF was automatically created by SolidWorks to URDF Exporter! Originally created by Stephen Brawner (brawner@gmail.com) 
     Commit Version: 1.6.0-4-g7f85cfe  Build Version: 1.6.7995.38578
     For more information, please see http://wiki.ros.org/sw_urdf_exporter -->
<robot
  name="rag1_urdf">
  <link
    name="base_link">
    <inertial>
      <origin
        xyz="-1.31849976402008E-05 0.0656951506509105 -0.0173908005318475"
        rpy="0 0 0" />
      <mass
        value="0.683305968410665" />
      <inertia
        ixx="0.000890187139462137"
        ixy="-1.97718495783513E-07"
        ixz="-8.57363116604806E-08"
        iyy="0.000884988878021512"
        iyz="4.77625369638664E-07"
        izz="0.00172923308299827" />
    </inertial>
    <visual>
      <origin
        xyz="0 0 0"
        rpy="0 0 0" />
      <geometry>
        <mesh
          filename="package://rag1_urdf/meshes/base_link.STL" />
      </geometry>
      <material
        name="">
        <color
          rgba="0.792156862745098 0.819607843137255 0.933333333333333 1" />
      </material>
    </visual>
    <collision>
      <origin
        xyz="0 0 0"
        rpy="0 0 0" />
      <geometry>
        <mesh
          filename="package://rag1_urdf/meshes/base_link.STL" />
      </geometry>
    </collision>
  </link>
  <link
    name="Link_1">
    <inertial>
      <origin
        xyz="-0.00072476 -0.0091715 0.051064"
        rpy="0 0 0" />
      <mass
        value="0.85721" />
      <inertia
        ixx="0.00081577"
        ixy="3.1171E-06"
        ixz="3.1074E-07"
        iyy="0.0013679"
        iyz="3.6148E-08"
        izz="0.0011156" />
    </inertial>
    <visual>
      <origin
        xyz="0 0 0"
        rpy="0 0 0" />
      <geometry>
        <mesh
          filename="package://rag1_urdf/meshes/Link_1.STL" />
      </geometry>
      <material
        name="">
        <color
          rgba="0.79216 0.81961 0.93333 1" />
      </material>
    </visual>
    <collision>
      <origin
        xyz="0 0 0"
        rpy="0 0 0" />
      <geometry>
        <mesh
          filename="package://rag1_urdf/meshes/Link_1.STL" />
      </geometry>
    </collision>
  </link>
  <joint
    name="Joint_1"
    type="continuous">
    <origin
      xyz="0 0 0.0199999999999999"
      rpy="0 0 0" />
    <parent
      link="base_link" />
    <child
      link="Link_1" />
    <axis
      xyz="0 0 1" />
  </joint>
  <link
    name="Link_2">
    <inertial>
      <origin
        xyz="0.14547 -0.00083736 5.3337E-08"
        rpy="0 0 0" />
      <mass
        value="0.39125" />
      <inertia
        ixx="0.00019198"
        ixy="7.4305E-06"
        ixz="-3.1277E-10"
        iyy="0.0014828"
        iyz="-4.9972E-10"
        izz="0.0013994" />
    </inertial>
    <visual>
      <origin
        xyz="0 0 0"
        rpy="0 0 0" />
      <geometry>
        <mesh
          filename="package://rag1_urdf/meshes/Link_2.STL" />
      </geometry>
      <material
        name="">
        <color
          rgba="0.79216 0.81961 0.93333 1" />
      </material>
    </visual>
    <collision>
      <origin
        xyz="0 0 0"
        rpy="0 0 0" />
      <geometry>
        <mesh
          filename="package://rag1_urdf/meshes/Link_2.STL" />
      </geometry>
    </collision>
  </link>
  <joint
    name="Joint_2"
    type="continuous">
    <origin
      xyz="0 0 0.059"
      rpy="0 0 0" />
    <parent
      link="Link_1" />
    <child
      link="Link_2" />
    <axis
      xyz="0.00575627201464716 0.999983432529006 0" />
  </joint>
  <link
    name="Link_3">
    <inertial>
      <origin
        xyz="0.0035968 -0.0045481 0.03447"
        rpy="0 0 0" />
      <mass
        value="0.15243" />
      <inertia
        ixx="0.00016647"
        ixy="1.2036E-07"
        ixz="-1.2437E-05"
        iyy="0.00018738"
        iyz="7.1596E-08"
        izz="4.9441E-05" />
    </inertial>
    <visual>
      <origin
        xyz="0 0 0"
        rpy="0 0 0" />
      <geometry>
        <mesh
          filename="package://rag1_urdf/meshes/Link_3.STL" />
      </geometry>
      <material
        name="">
        <color
          rgba="0.79216 0.81961 0.93333 1" />
      </material>
    </visual>
    <collision>
      <origin
        xyz="0 0 0"
        rpy="0 0 0" />
      <geometry>
        <mesh
          filename="package://rag1_urdf/meshes/Link_3.STL" />
      </geometry>
    </collision>
  </link>
  <joint
    name="Joint_3"
    type="continuous">
    <origin
      xyz="0.249995858132252 -0.00143906800366216 0"
      rpy="0 0 0" />
    <parent
      link="Link_2" />
    <child
      link="Link_3" />
    <axis
      xyz="0.00575627201464868 0.999983432529006 0" />
  </joint>
  <link
    name="Link_4">
    <inertial>
      <origin
        xyz="-0.0012975 7.4698E-06 9.5416E-09"
        rpy="0 0 0" />
      <mass
        value="0.011345" />
      <inertia
        ixx="9.8863E-07"
        ixy="-1.6766E-09"
        ixz="2.0572E-12"
        iyy="6.9731E-07"
        iyz="-6.4158E-13"
        izz="6.1521E-07" />
    </inertial>
    <visual>
      <origin
        xyz="0 0 0"
        rpy="0 0 0" />
      <geometry>
        <mesh
          filename="package://rag1_urdf/meshes/Link_4.STL" />
      </geometry>
      <material
        name="">
        <color
          rgba="0.79216 0.81961 0.93333 1" />
      </material>
    </visual>
    <collision>
      <origin
        xyz="0 0 0"
        rpy="0 0 0" />
      <geometry>
        <mesh
          filename="package://rag1_urdf/meshes/Link_4.STL" />
      </geometry>
    </collision>
  </link>
  <joint
    name="Joint_4"
    type="continuous">
    <origin
      xyz="0.0125432077794445 -7.22033121414514E-05 0.119342627444194"
      rpy="0 0 0" />
    <parent
      link="Link_3" />
    <child
      link="Link_4" />
    <axis
      xyz="-0.00575627201464868 -0.999983432529006 0" />
  </joint>
  <link
    name="Link_5">
    <inertial>
      <origin
        xyz="-0.0042676 2.4566E-05 5.5511E-17"
        rpy="0 0 0" />
      <mass
        value="0.003122" />
      <inertia
        ixx="1.832E-07"
        ixy="-3.2716E-10"
        ixz="-8.3485E-23"
        iyy="1.2636E-07"
        iyz="7.6282E-23"
        izz="1.0018E-07" />
    </inertial>
    <visual>
      <origin
        xyz="0 0 0"
        rpy="0 0 0" />
      <geometry>
        <mesh
          filename="package://rag1_urdf/meshes/Link_5.STL" />
      </geometry>
      <material
        name="">
        <color
          rgba="0.79216 0.81961 0.93333 1" />
      </material>
    </visual>
    <collision>
      <origin
        xyz="0 0 0"
        rpy="0 0 0" />
      <geometry>
        <mesh
          filename="package://rag1_urdf/meshes/Link_5.STL" />
      </geometry>
    </collision>
  </link>
  <joint
    name="Joint_5"
    type="continuous">
    <origin
      xyz="0 0 0"
      rpy="0 0 0" />
    <parent
      link="Link_4" />
    <child
      link="Link_5" />
    <axis
      xyz="0 0 1" />
  </joint>
  <link
    name="Link_6">
    <inertial>
      <origin
        xyz="0.0015 -8.6344E-06 5.5511E-17"
        rpy="0 0 0" />
      <mass
        value="9.8175E-05" />
      <inertia
        ixx="3.068E-10"
        ixy="2.9433E-13"
        ixz="-3.1068E-26"
        iyy="3.5793E-10"
        iyz="1.0097E-26"
        izz="3.5793E-10" />
    </inertial>
    <visual>
      <origin
        xyz="0 0 0"
        rpy="0 0 0" />
      <geometry>
        <mesh
          filename="package://rag1_urdf/meshes/Link_6.STL" />
      </geometry>
      <material
        name="">
        <color
          rgba="0.79216 0.81961 0.93333 1" />
      </material>
    </visual>
    <collision>
      <origin
        xyz="0 0 0"
        rpy="0 0 0" />
      <geometry>
        <mesh
          filename="package://rag1_urdf/meshes/Link_6.STL" />
      </geometry>
    </collision>
  </link>
  <joint
    name="Joint_6"
    type="continuous">
    <origin
      xyz="0 0 0"
      rpy="0 0 0" />
    <parent
      link="Link_5" />
    <child
      link="Link_6" />
    <axis
      xyz="-0.999983432529006 0.00575627201464856 0" />
  </joint>
</robot>